[2022-11-20 09:06:09,060] {taskinstance.py:903} INFO - Dependencies all met for <TaskInstance: first_dag.first_function_execute 2022-11-19T00:00:00+00:00 [queued]>
[2022-11-20 09:06:09,087] {taskinstance.py:903} INFO - Dependencies all met for <TaskInstance: first_dag.first_function_execute 2022-11-19T00:00:00+00:00 [queued]>
[2022-11-20 09:06:09,088] {taskinstance.py:1094} INFO - 
--------------------------------------------------------------------------------
[2022-11-20 09:06:09,089] {taskinstance.py:1095} INFO - Starting attempt 2 of 3
[2022-11-20 09:06:09,089] {taskinstance.py:1096} INFO - 
--------------------------------------------------------------------------------
[2022-11-20 09:06:09,101] {taskinstance.py:1114} INFO - Executing <Task(PythonOperator): first_function_execute> on 2022-11-19T00:00:00+00:00
[2022-11-20 09:06:09,105] {standard_task_runner.py:52} INFO - Started process 503 to run task
[2022-11-20 09:06:09,109] {standard_task_runner.py:76} INFO - Running: ['***', 'tasks', 'run', 'first_dag', 'first_function_execute', '2022-11-19T00:00:00+00:00', '--job-id', '9', '--pool', 'default_pool', '--raw', '--subdir', 'DAGS_FOLDER/first_dag.py', '--cfg-path', '/tmp/tmp3xl19uol', '--error-file', '/tmp/tmp08g6en24']
[2022-11-20 09:06:09,111] {standard_task_runner.py:77} INFO - Job 9: Subtask first_function_execute
[2022-11-20 09:06:09,161] {logging_mixin.py:109} INFO - Running <TaskInstance: first_dag.first_function_execute 2022-11-19T00:00:00+00:00 [running]> on host c451c373dc68
[2022-11-20 09:06:09,240] {taskinstance.py:1253} INFO - Exporting the following env vars:
AIRFLOW_CTX_DAG_OWNER=***
AIRFLOW_CTX_DAG_ID=first_dag
AIRFLOW_CTX_TASK_ID=first_function_execute
AIRFLOW_CTX_EXECUTION_DATE=2022-11-19T00:00:00+00:00
AIRFLOW_CTX_DAG_RUN_ID=scheduled__2022-11-19T00:00:00+00:00
[2022-11-20 09:06:09,246] {taskinstance.py:1462} ERROR - Task failed with exception
Traceback (most recent call last):
  File "/home/airflow/.local/lib/python3.6/site-packages/airflow/models/taskinstance.py", line 1164, in _run_raw_task
    self._prepare_and_execute_task_with_callbacks(context, task)
  File "/home/airflow/.local/lib/python3.6/site-packages/airflow/models/taskinstance.py", line 1282, in _prepare_and_execute_task_with_callbacks
    result = self._execute_task(context, task_copy)
  File "/home/airflow/.local/lib/python3.6/site-packages/airflow/models/taskinstance.py", line 1312, in _execute_task
    result = task_copy.execute(context=context)
  File "/home/airflow/.local/lib/python3.6/site-packages/airflow/operators/python.py", line 150, in execute
    return_value = self.execute_callable()
  File "/home/airflow/.local/lib/python3.6/site-packages/airflow/operators/python.py", line 161, in execute_callable
    return self.python_callable(*self.op_args, **self.op_kwargs)
  File "/opt/airflow/dags/first_dag.py", line 13, in first_function_execute
    print("hello world : {}".format(variable))
NameError: name 'variable' is not defined
[2022-11-20 09:06:09,257] {taskinstance.py:1512} INFO - Marking task as UP_FOR_RETRY. dag_id=first_dag, task_id=first_function_execute, execution_date=20221119T000000, start_date=20221120T090609, end_date=20221120T090609
[2022-11-20 09:06:09,327] {local_task_job.py:151} INFO - Task exited with return code 1
[2022-11-20 09:06:09,352] {local_task_job.py:261} INFO - 0 downstream tasks scheduled from follow-on schedule check
