[2022-11-20 11:49:22,813] {taskinstance.py:903} INFO - Dependencies all met for <TaskInstance: first_dag.first_function_execute 2022-11-19T00:00:00+00:00 [queued]>
[2022-11-20 11:49:22,840] {taskinstance.py:903} INFO - Dependencies all met for <TaskInstance: first_dag.first_function_execute 2022-11-19T00:00:00+00:00 [queued]>
[2022-11-20 11:49:22,841] {taskinstance.py:1094} INFO - 
--------------------------------------------------------------------------------
[2022-11-20 11:49:22,841] {taskinstance.py:1095} INFO - Starting attempt 5 of 6
[2022-11-20 11:49:22,842] {taskinstance.py:1096} INFO - 
--------------------------------------------------------------------------------
[2022-11-20 11:49:22,857] {taskinstance.py:1114} INFO - Executing <Task(PythonOperator): first_function_execute> on 2022-11-19T00:00:00+00:00
[2022-11-20 11:49:22,863] {standard_task_runner.py:52} INFO - Started process 3894 to run task
[2022-11-20 11:49:22,871] {standard_task_runner.py:76} INFO - Running: ['***', 'tasks', 'run', 'first_dag', 'first_function_execute', '2022-11-19T00:00:00+00:00', '--job-id', '12', '--pool', 'default_pool', '--raw', '--subdir', 'DAGS_FOLDER/first_dag.py', '--cfg-path', '/tmp/tmp6tpbelgr', '--error-file', '/tmp/tmpmvx9mjwg']
[2022-11-20 11:49:22,874] {standard_task_runner.py:77} INFO - Job 12: Subtask first_function_execute
[2022-11-20 11:49:22,954] {logging_mixin.py:109} INFO - Running <TaskInstance: first_dag.first_function_execute 2022-11-19T00:00:00+00:00 [running]> on host c451c373dc68
[2022-11-20 11:49:23,117] {taskinstance.py:1253} INFO - Exporting the following env vars:
AIRFLOW_CTX_DAG_OWNER=***
AIRFLOW_CTX_DAG_ID=first_dag
AIRFLOW_CTX_TASK_ID=first_function_execute
AIRFLOW_CTX_EXECUTION_DATE=2022-11-19T00:00:00+00:00
AIRFLOW_CTX_DAG_RUN_ID=scheduled__2022-11-19T00:00:00+00:00
[2022-11-20 11:49:23,119] {logging_mixin.py:109} INFO - first function execute
[2022-11-20 11:49:23,136] {taskinstance.py:1462} ERROR - Task failed with exception
Traceback (most recent call last):
  File "/home/airflow/.local/lib/python3.6/site-packages/airflow/models/taskinstance.py", line 1164, in _run_raw_task
    self._prepare_and_execute_task_with_callbacks(context, task)
  File "/home/airflow/.local/lib/python3.6/site-packages/airflow/models/taskinstance.py", line 1282, in _prepare_and_execute_task_with_callbacks
    result = self._execute_task(context, task_copy)
  File "/home/airflow/.local/lib/python3.6/site-packages/airflow/models/taskinstance.py", line 1312, in _execute_task
    result = task_copy.execute(context=context)
  File "/home/airflow/.local/lib/python3.6/site-packages/airflow/operators/python.py", line 150, in execute
    return_value = self.execute_callable()
  File "/home/airflow/.local/lib/python3.6/site-packages/airflow/operators/python.py", line 161, in execute_callable
    return self.python_callable(*self.op_args, **self.op_kwargs)
  File "/opt/airflow/dags/first_dag.py", line 14, in first_function_execute
    return "hello world"+variable
NameError: name 'variable' is not defined
[2022-11-20 11:49:23,147] {taskinstance.py:1512} INFO - Marking task as UP_FOR_RETRY. dag_id=first_dag, task_id=first_function_execute, execution_date=20221119T000000, start_date=20221120T114922, end_date=20221120T114923
[2022-11-20 11:49:23,176] {local_task_job.py:151} INFO - Task exited with return code 1
[2022-11-20 11:49:23,224] {local_task_job.py:261} INFO - 0 downstream tasks scheduled from follow-on schedule check
